<?xml version="1.0" ?>
<robot name="mistletoe" xmlns:xacro="http://www.ros.org/wiki/xacro">

<xacro:include filename="$(find mistletoe_description)/urdf/materials.xacro" />
<xacro:include filename="$(find mistletoe_description)/urdf/mistletoe.trans" />
<link name="base_link">
  <inertial>
    <origin xyz="-0.06657859086794671 0.12180227598730436 0.027661254547312438" rpy="0 0 0"/>
    <mass value="2.781822888066483"/>
    <inertia ixx="0.012347" iyy="0.169247" izz="0.177361" ixy="-3e-06" iyz="0.0" ixz="-4.1e-05"/>
  </inertial>
  <visual>
    <origin xyz="0 0 0" rpy="0 0 0"/>
    <geometry>
      <mesh filename="package://mistletoe_description/meshes/base_link.stl" scale="0.001 0.001 0.001"/>
    </geometry>
    <material name="plastic_glossy_black"/>
  </visual>
  <collision>
    <origin xyz="0 0 0" rpy="0 0 0"/>
    <geometry>
      <mesh filename="package://mistletoe_description/meshes/base_link.stl" scale="0.001 0.001 0.001"/>
    </geometry>
  </collision>
</link>

<link name="ANKLE_v4_1">
  <inertial>
    <origin xyz="0.05969551525022496 0.02164768809099367 -0.034465214950969866" rpy="0 0 0"/>
    <mass value="0.0707595437253254"/>
    <inertia ixx="5.5e-05" iyy="0.000193" izz="0.000147" ixy="-4e-06" iyz="3e-06" ixz="8e-05"/>
  </inertial>
  <visual>
    <origin xyz="-0.002 0.0695 -0.025" rpy="0 0 0"/>
    <geometry>
      <mesh filename="package://mistletoe_description/meshes/ANKLE_v4_1.stl" scale="0.001 0.001 0.001"/>
    </geometry>
    <material name="plastic_glossy_black"/>
  </visual>
  <collision>
    <origin xyz="-0.002 0.0695 -0.025" rpy="0 0 0"/>
    <geometry>
      <mesh filename="package://mistletoe_description/meshes/ANKLE_v4_1.stl" scale="0.001 0.001 0.001"/>
    </geometry>
  </collision>
</link>

<link name="ACTUATOR_V2.1__KNEE__v10_1">
  <inertial>
    <origin xyz="-0.053095905532469054 -0.06025650205456463 -6.906335524088647e-06" rpy="0 0 0"/>
    <mass value="0.6687419456686833"/>
    <inertia ixx="0.000581" iyy="0.003897" izz="0.004059" ixy="-0.000492" iyz="0.0" ixz="0.0"/>
  </inertial>
  <visual>
    <origin xyz="-0.17787 0.025 -0.025" rpy="0 0 0"/>
    <geometry>
      <mesh filename="package://mistletoe_description/meshes/ACTUATOR_V2.1__KNEE__v10_1.stl" scale="0.001 0.001 0.001"/>
    </geometry>
    <material name="plastic_glossy_black"/>
  </visual>
  <collision>
    <origin xyz="-0.17787 0.025 -0.025" rpy="0 0 0"/>
    <geometry>
      <mesh filename="package://mistletoe_description/meshes/ACTUATOR_V2.1__KNEE__v10_1.stl" scale="0.001 0.001 0.001"/>
    </geometry>
  </collision>
</link>

<link name="Hip_1">
  <inertial>
    <origin xyz="-0.1675167715088863 0.008238257074782459 -5.174132261531739e-09" rpy="0 0 0"/>
    <mass value="0.5600707780907046"/>
    <inertia ixx="0.000428" iyy="0.004847" izz="0.004917" ixy="0.000319" iyz="-0.0" ixz="-0.0"/>
  </inertial>
  <visual>
    <origin xyz="-0.255776 -0.0 -0.025" rpy="0 0 0"/>
    <geometry>
      <mesh filename="package://mistletoe_description/meshes/Hip_1.stl" scale="0.001 0.001 0.001"/>
    </geometry>
    <material name="plastic_glossy_black"/>
  </visual>
  <collision>
    <origin xyz="-0.255776 -0.0 -0.025" rpy="0 0 0"/>
    <geometry>
      <mesh filename="package://mistletoe_description/meshes/Hip_1.stl" scale="0.001 0.001 0.001"/>
    </geometry>
  </collision>
</link>

<link name="Hip_2">
  <inertial>
    <origin xyz="-0.1675167715088863 -0.008238257074782096 5.174132615415328e-09" rpy="0 0 0"/>
    <mass value="0.5600707780907046"/>
    <inertia ixx="0.000428" iyy="0.004847" izz="0.004917" ixy="-0.000319" iyz="-0.0" ixz="0.0"/>
  </inertial>
  <visual>
    <origin xyz="-0.255776 -0.243608 -0.025" rpy="0 0 0"/>
    <geometry>
      <mesh filename="package://mistletoe_description/meshes/Hip_2.stl" scale="0.001 0.001 0.001"/>
    </geometry>
    <material name="plastic_glossy_black"/>
  </visual>
  <collision>
    <origin xyz="-0.255776 -0.243608 -0.025" rpy="0 0 0"/>
    <geometry>
      <mesh filename="package://mistletoe_description/meshes/Hip_2.stl" scale="0.001 0.001 0.001"/>
    </geometry>
  </collision>
</link>

<link name="ACTUATOR_V2.1__KNEE__v10_2">
  <inertial>
    <origin xyz="-0.05309590553246825 0.0602565020545649 6.906335525407037e-06" rpy="0 0 0"/>
    <mass value="0.6687419456686833"/>
    <inertia ixx="0.000581" iyy="0.003897" izz="0.004059" ixy="0.000492" iyz="0.0" ixz="-0.0"/>
  </inertial>
  <visual>
    <origin xyz="-0.17787 -0.268608 -0.025" rpy="0 0 0"/>
    <geometry>
      <mesh filename="package://mistletoe_description/meshes/ACTUATOR_V2.1__KNEE__v10_2.stl" scale="0.001 0.001 0.001"/>
    </geometry>
    <material name="plastic_glossy_black"/>
  </visual>
  <collision>
    <origin xyz="-0.17787 -0.268608 -0.025" rpy="0 0 0"/>
    <geometry>
      <mesh filename="package://mistletoe_description/meshes/ACTUATOR_V2.1__KNEE__v10_2.stl" scale="0.001 0.001 0.001"/>
    </geometry>
  </collision>
</link>

<link name="ANKLE_v4_2">
  <inertial>
    <origin xyz="0.059695509319545356 -0.021647688090992268 -0.034465225223213346" rpy="0 0 0"/>
    <mass value="0.0707595437253254"/>
    <inertia ixx="5.5e-05" iyy="0.000193" izz="0.000147" ixy="4e-06" iyz="-3e-06" ixz="8e-05"/>
  </inertial>
  <visual>
    <origin xyz="-0.002 -0.313108 -0.025" rpy="0 0 0"/>
    <geometry>
      <mesh filename="package://mistletoe_description/meshes/ANKLE_v4_2.stl" scale="0.001 0.001 0.001"/>
    </geometry>
    <material name="plastic_glossy_black"/>
  </visual>
  <collision>
    <origin xyz="-0.002 -0.313108 -0.025" rpy="0 0 0"/>
    <geometry>
      <mesh filename="package://mistletoe_description/meshes/ANKLE_v4_2.stl" scale="0.001 0.001 0.001"/>
    </geometry>
  </collision>
</link>

<link name="Hip_3">
  <inertial>
    <origin xyz="0.16751677150888733 0.008238257074779359 5.174144071529163e-09" rpy="0 0 0"/>
    <mass value="0.5600707780907046"/>
    <inertia ixx="0.000428" iyy="0.004847" izz="0.004917" ixy="-0.000319" iyz="0.0" ixz="-0.0"/>
  </inertial>
  <visual>
    <origin xyz="0.389589 0.0 -0.025" rpy="0 0 0"/>
    <geometry>
      <mesh filename="package://mistletoe_description/meshes/Hip_3.stl" scale="0.001 0.001 0.001"/>
    </geometry>
    <material name="plastic_glossy_black"/>
  </visual>
  <collision>
    <origin xyz="0.389589 0.0 -0.025" rpy="0 0 0"/>
    <geometry>
      <mesh filename="package://mistletoe_description/meshes/Hip_3.stl" scale="0.001 0.001 0.001"/>
    </geometry>
  </collision>
</link>

<link name="Hip_4">
  <inertial>
    <origin xyz="0.16751677150888733 -0.008238257074783317 -5.174120409900951e-09" rpy="0 0 0"/>
    <mass value="0.5600707780907046"/>
    <inertia ixx="0.000428" iyy="0.004847" izz="0.004917" ixy="0.000319" iyz="0.0" ixz="0.0"/>
  </inertial>
  <visual>
    <origin xyz="0.389589 -0.243608 -0.025" rpy="0 0 0"/>
    <geometry>
      <mesh filename="package://mistletoe_description/meshes/Hip_4.stl" scale="0.001 0.001 0.001"/>
    </geometry>
    <material name="plastic_glossy_black"/>
  </visual>
  <collision>
    <origin xyz="0.389589 -0.243608 -0.025" rpy="0 0 0"/>
    <geometry>
      <mesh filename="package://mistletoe_description/meshes/Hip_4.stl" scale="0.001 0.001 0.001"/>
    </geometry>
  </collision>
</link>

<link name="ACTUATOR_V2.1__KNEE__v10_3">
  <inertial>
    <origin xyz="0.05309590553246918 -0.06025650205456722 6.906335536540492e-06" rpy="0 0 0"/>
    <mass value="0.6687419456686833"/>
    <inertia ixx="0.000581" iyy="0.003897" izz="0.004059" ixy="0.000492" iyz="-0.0" ixz="0.0"/>
  </inertial>
  <visual>
    <origin xyz="0.311683 0.025 -0.025" rpy="0 0 0"/>
    <geometry>
      <mesh filename="package://mistletoe_description/meshes/ACTUATOR_V2.1__KNEE__v10_3.stl" scale="0.001 0.001 0.001"/>
    </geometry>
    <material name="plastic_glossy_black"/>
  </visual>
  <collision>
    <origin xyz="0.311683 0.025 -0.025" rpy="0 0 0"/>
    <geometry>
      <mesh filename="package://mistletoe_description/meshes/ACTUATOR_V2.1__KNEE__v10_3.stl" scale="0.001 0.001 0.001"/>
    </geometry>
  </collision>
</link>

<link name="ACTUATOR_V2.1__KNEE__v10_4">
  <inertial>
    <origin xyz="0.05309590553246907 0.06025650205456318 -6.906335511872724e-06" rpy="0 0 0"/>
    <mass value="0.6687419456686833"/>
    <inertia ixx="0.000581" iyy="0.003897" izz="0.004059" ixy="-0.000492" iyz="-0.0" ixz="-0.0"/>
  </inertial>
  <visual>
    <origin xyz="0.311683 -0.268608 -0.025" rpy="0 0 0"/>
    <geometry>
      <mesh filename="package://mistletoe_description/meshes/ACTUATOR_V2.1__KNEE__v10_4.stl" scale="0.001 0.001 0.001"/>
    </geometry>
    <material name="plastic_glossy_black"/>
  </visual>
  <collision>
    <origin xyz="0.311683 -0.268608 -0.025" rpy="0 0 0"/>
    <geometry>
      <mesh filename="package://mistletoe_description/meshes/ACTUATOR_V2.1__KNEE__v10_4.stl" scale="0.001 0.001 0.001"/>
    </geometry>
  </collision>
</link>

<link name="ANKLE_v4_3">
  <inertial>
    <origin xyz="-0.059695515250226594 -0.021647688090993877 -0.034465214950958015" rpy="0 0 0"/>
    <mass value="0.0707595437253254"/>
    <inertia ixx="5.5e-05" iyy="0.000193" izz="0.000147" ixy="-4e-06" iyz="-3e-06" ixz="-8e-05"/>
  </inertial>
  <visual>
    <origin xyz="0.135813 -0.313108 -0.025" rpy="0 0 0"/>
    <geometry>
      <mesh filename="package://mistletoe_description/meshes/ANKLE_v4_3.stl" scale="0.001 0.001 0.001"/>
    </geometry>
    <material name="plastic_glossy_black"/>
  </visual>
  <collision>
    <origin xyz="0.135813 -0.313108 -0.025" rpy="0 0 0"/>
    <geometry>
      <mesh filename="package://mistletoe_description/meshes/ANKLE_v4_3.stl" scale="0.001 0.001 0.001"/>
    </geometry>
  </collision>
</link>

<link name="ANKLE_v4_4">
  <inertial>
    <origin xyz="-0.05969550931954576 0.02164768809099009 -0.03446522522320032" rpy="0 0 0"/>
    <mass value="0.0707595437253254"/>
    <inertia ixx="5.5e-05" iyy="0.000193" izz="0.000147" ixy="4e-06" iyz="3e-06" ixz="-8e-05"/>
  </inertial>
  <visual>
    <origin xyz="0.135813 0.0695 -0.025" rpy="0 0 0"/>
    <geometry>
      <mesh filename="package://mistletoe_description/meshes/ANKLE_v4_4.stl" scale="0.001 0.001 0.001"/>
    </geometry>
    <material name="plastic_glossy_black"/>
  </visual>
  <collision>
    <origin xyz="0.135813 0.0695 -0.025" rpy="0 0 0"/>
    <geometry>
      <mesh filename="package://mistletoe_description/meshes/ANKLE_v4_4.stl" scale="0.001 0.001 0.001"/>
    </geometry>
  </collision>
</link>

<joint name="Revolute 11" type="continuous">
  <origin xyz="-0.17587 -0.0445 0.0" rpy="0 0 0"/>
  <parent link="ACTUATOR_V2.1__KNEE__v10_1"/>
  <child link="ANKLE_v4_1"/>
  <axis xyz="0.0 -1.0 0.0"/>
</joint>

<joint name="Revolute 12" type="continuous">
  <origin xyz="-0.077906 -0.025 0.0" rpy="0 0 0"/>
  <parent link="Hip_1"/>
  <child link="ACTUATOR_V2.1__KNEE__v10_1"/>
  <axis xyz="0.0 1.0 -0.0"/>
</joint>

<joint name="Revolute 15" type="continuous">
  <origin xyz="0.255776 0.0 0.025" rpy="0 0 0"/>
  <parent link="base_link"/>
  <child link="Hip_1"/>
  <axis xyz="-1.0 0.0 0.0"/>
</joint>

<joint name="Revolute 16" type="continuous">
  <origin xyz="0.255776 0.243608 0.025" rpy="0 0 0"/>
  <parent link="base_link"/>
  <child link="Hip_2"/>
  <axis xyz="1.0 0.0 -0.0"/>
</joint>

<joint name="Revolute 17" type="continuous">
  <origin xyz="-0.077906 0.025 0.0" rpy="0 0 0"/>
  <parent link="Hip_2"/>
  <child link="ACTUATOR_V2.1__KNEE__v10_2"/>
  <axis xyz="0.0 -1.0 0.0"/>
</joint>

<joint name="Revolute 18" type="continuous">
  <origin xyz="-0.17587 0.0445 0.0" rpy="0 0 0"/>
  <parent link="ACTUATOR_V2.1__KNEE__v10_2"/>
  <child link="ANKLE_v4_2"/>
  <axis xyz="0.0 1.0 -0.0"/>
</joint>

<joint name="Revolute 20" type="continuous">
  <origin xyz="-0.389589 0.0 0.025" rpy="0 0 0"/>
  <parent link="base_link"/>
  <child link="Hip_3"/>
  <axis xyz="1.0 0.0 -0.0"/>
</joint>

<joint name="Revolute 21" type="continuous">
  <origin xyz="-0.389589 0.243608 0.025" rpy="0 0 0"/>
  <parent link="base_link"/>
  <child link="Hip_4"/>
  <axis xyz="1.0 0.0 -0.0"/>
</joint>

<joint name="Revolute 22" type="continuous">
  <origin xyz="0.077906 -0.025 0.0" rpy="0 0 0"/>
  <parent link="Hip_3"/>
  <child link="ACTUATOR_V2.1__KNEE__v10_3"/>
  <axis xyz="-0.0 1.0 -0.0"/>
</joint>

<joint name="Revolute 23" type="continuous">
  <origin xyz="0.077906 0.025 0.0" rpy="0 0 0"/>
  <parent link="Hip_4"/>
  <child link="ACTUATOR_V2.1__KNEE__v10_4"/>
  <axis xyz="-0.0 -1.0 -0.0"/>
</joint>

<joint name="Revolute 24" type="continuous">
  <origin xyz="0.17587 0.0445 0.0" rpy="0 0 0"/>
  <parent link="ACTUATOR_V2.1__KNEE__v10_4"/>
  <child link="ANKLE_v4_3"/>
  <axis xyz="-0.0 1.0 0.0"/>
</joint>

<joint name="Revolute 25" type="continuous">
  <origin xyz="0.17587 -0.0445 0.0" rpy="0 0 0"/>
  <parent link="ACTUATOR_V2.1__KNEE__v10_3"/>
  <child link="ANKLE_v4_4"/>
  <axis xyz="-0.0 -1.0 0.0"/>
</joint>

</robot>
