<?xml version="1.0" ?>
<!-- =================================================================================== -->
<!-- |    This document was autogenerated by xacro from mistletoe.xacro                | -->
<!-- |    EDITING THIS FILE BY HAND IS NOT RECOMMENDED                                 | -->
<!-- =================================================================================== -->
<robot name="mistletoe">
  <material name="silver_default">
    <color rgba="0.700 0.700 0.700 1.000"/>
  </material>
  <material name="plastic_glossy_black">
    <color rgba="0.09803921568627451 0.09803921568627451 0.09803921568627451 1.0"/>
  </material>
  <transmission name="LEG_3_KFE_tran">
    <type>transmission_interface/SimpleTransmission</type>
    <joint name="LEG_3_KFE">
      <hardwareInterface>hardware_interface/EffortJointInterface</hardwareInterface>
    </joint>
    <actuator name="LEG_3_KFE_actr">
      <hardwareInterface>hardware_interface/EffortJointInterface</hardwareInterface>
      <mechanicalReduction>1</mechanicalReduction>
    </actuator>
  </transmission>
  <transmission name="LEG_3_HFE_tran">
    <type>transmission_interface/SimpleTransmission</type>
    <joint name="LEG_3_HFE">
      <hardwareInterface>hardware_interface/EffortJointInterface</hardwareInterface>
    </joint>
    <actuator name="LEG_3_HFE_actr">
      <hardwareInterface>hardware_interface/EffortJointInterface</hardwareInterface>
      <mechanicalReduction>1</mechanicalReduction>
    </actuator>
  </transmission>
  <transmission name="LEG_3_HAA_tran">
    <type>transmission_interface/SimpleTransmission</type>
    <joint name="LEG_3_HAA">
      <hardwareInterface>hardware_interface/EffortJointInterface</hardwareInterface>
    </joint>
    <actuator name="LEG_3_HAA_actr">
      <hardwareInterface>hardware_interface/EffortJointInterface</hardwareInterface>
      <mechanicalReduction>1</mechanicalReduction>
    </actuator>
  </transmission>
  <transmission name="LEG_4_HAA_tran">
    <type>transmission_interface/SimpleTransmission</type>
    <joint name="LEG_4_HAA">
      <hardwareInterface>hardware_interface/EffortJointInterface</hardwareInterface>
    </joint>
    <actuator name="LEG_4_HAA_actr">
      <hardwareInterface>hardware_interface/EffortJointInterface</hardwareInterface>
      <mechanicalReduction>1</mechanicalReduction>
    </actuator>
  </transmission>
  <transmission name="LEG_4_HFE_tran">
    <type>transmission_interface/SimpleTransmission</type>
    <joint name="LEG_4_HFE">
      <hardwareInterface>hardware_interface/EffortJointInterface</hardwareInterface>
    </joint>
    <actuator name="LEG_4_HFE_actr">
      <hardwareInterface>hardware_interface/EffortJointInterface</hardwareInterface>
      <mechanicalReduction>1</mechanicalReduction>
    </actuator>
  </transmission>
  <transmission name="LEG_4_KFE_tran">
    <type>transmission_interface/SimpleTransmission</type>
    <joint name="LEG_4_KFE">
      <hardwareInterface>hardware_interface/EffortJointInterface</hardwareInterface>
    </joint>
    <actuator name="LEG_4_KFE_actr">
      <hardwareInterface>hardware_interface/EffortJointInterface</hardwareInterface>
      <mechanicalReduction>1</mechanicalReduction>
    </actuator>
  </transmission>
  <transmission name="LEG_1_HAA_tran">
    <type>transmission_interface/SimpleTransmission</type>
    <joint name="LEG_1_HAA">
      <hardwareInterface>hardware_interface/EffortJointInterface</hardwareInterface>
    </joint>
    <actuator name="LEG_1_HAA_actr">
      <hardwareInterface>hardware_interface/EffortJointInterface</hardwareInterface>
      <mechanicalReduction>1</mechanicalReduction>
    </actuator>
  </transmission>
  <transmission name="LEG_2_HAA_tran">
    <type>transmission_interface/SimpleTransmission</type>
    <joint name="LEG_2_HAA">
      <hardwareInterface>hardware_interface/EffortJointInterface</hardwareInterface>
    </joint>
    <actuator name="LEG_2_HAA_actr">
      <hardwareInterface>hardware_interface/EffortJointInterface</hardwareInterface>
      <mechanicalReduction>1</mechanicalReduction>
    </actuator>
  </transmission>
  <transmission name="LEG_1_HFE_tran">
    <type>transmission_interface/SimpleTransmission</type>
    <joint name="LEG_1_HFE">
      <hardwareInterface>hardware_interface/EffortJointInterface</hardwareInterface>
    </joint>
    <actuator name="LEG_1_HFE_actr">
      <hardwareInterface>hardware_interface/EffortJointInterface</hardwareInterface>
      <mechanicalReduction>1</mechanicalReduction>
    </actuator>
  </transmission>
  <transmission name="LEG_2_HFE_tran">
    <type>transmission_interface/SimpleTransmission</type>
    <joint name="LEG_2_HFE">
      <hardwareInterface>hardware_interface/EffortJointInterface</hardwareInterface>
    </joint>
    <actuator name="LEG_2_HFE_actr">
      <hardwareInterface>hardware_interface/EffortJointInterface</hardwareInterface>
      <mechanicalReduction>1</mechanicalReduction>
    </actuator>
  </transmission>
  <transmission name="LEG_2_KFE_tran">
    <type>transmission_interface/SimpleTransmission</type>
    <joint name="LEG_2_KFE">
      <hardwareInterface>hardware_interface/EffortJointInterface</hardwareInterface>
    </joint>
    <actuator name="LEG_2_KFE_actr">
      <hardwareInterface>hardware_interface/EffortJointInterface</hardwareInterface>
      <mechanicalReduction>1</mechanicalReduction>
    </actuator>
  </transmission>
  <transmission name="LEG_1_KFE_tran">
    <type>transmission_interface/SimpleTransmission</type>
    <joint name="LEG_1_KFE">
      <hardwareInterface>hardware_interface/EffortJointInterface</hardwareInterface>
    </joint>
    <actuator name="LEG_1_KFE_actr">
      <hardwareInterface>hardware_interface/EffortJointInterface</hardwareInterface>
      <mechanicalReduction>1</mechanicalReduction>
    </actuator>
  </transmission>
  <link name="base">
    <inertial>
      <origin rpy="0 0 0" xyz="-0.06657859086794671 0.12180227598730436 0.027661254547312438"/>
      <mass value="2.781822888066483"/>
      <inertia ixx="0.012347" ixy="-3e-06" ixz="-4.1e-05" iyy="0.169247" iyz="0.0" izz="0.177361"/>
    </inertial>
    <visual>
      <origin rpy="0 0 0" xyz="0 0 0"/>
      <geometry>
        <mesh filename="package://mistletoe_description/meshes/base_link.stl" scale="0.001 0.001 0.001"/>
      </geometry>
      <material name="plastic_glossy_black"/>
    </visual>
    <collision>
      <origin rpy="0 0 0" xyz="0 0 0"/>
      <geometry>
        <mesh filename="package://mistletoe_description/meshes/base_link.stl" scale="0.001 0.001 0.001"/>
      </geometry>
    </collision>
  </link>
  <link name="LEG_1_FOOT">
    <inertial>
      <origin rpy="0 0 0" xyz="0.05969551525022496 0.02164768809099367 -0.034465214950969866"/>
      <mass value="0.0707595437253254"/>
      <inertia ixx="5.5e-05" ixy="-4e-06" ixz="8e-05" iyy="0.000193" iyz="3e-06" izz="0.000147"/>
    </inertial>
    <visual>
      <origin rpy="0 0 0" xyz="-0.002 0.0695 -0.025"/>
      <geometry>
        <mesh filename="package://mistletoe_description/meshes/ANKLE_v4_1.stl" scale="0.001 0.001 0.001"/>
      </geometry>
      <material name="plastic_glossy_black"/>
    </visual>
    <collision>
      <origin rpy="0 0 0" xyz="-0.002 0.0695 -0.025"/>
      <geometry>
        <mesh filename="package://mistletoe_description/meshes/ANKLE_v4_1.stl" scale="0.001 0.001 0.001"/>
      </geometry>
    </collision>
  </link>
  <link name="LEG_1_THIGH">
    <inertial>
      <origin rpy="0 0 0" xyz="-0.053095905532469054 -0.06025650205456463 -6.906335524088647e-06"/>
      <mass value="0.6687419456686833"/>
      <inertia ixx="0.000581" ixy="-0.000492" ixz="0.0" iyy="0.003897" iyz="0.0" izz="0.004059"/>
    </inertial>
    <visual>
      <origin rpy="0 0 0" xyz="-0.17787 0.025 -0.025"/>
      <geometry>
        <mesh filename="package://mistletoe_description/meshes/ACTUATOR_V2.1__KNEE__v10_1.stl" scale="0.001 0.001 0.001"/>
      </geometry>
      <material name="plastic_glossy_black"/>
    </visual>
    <collision>
      <origin rpy="0 0 0" xyz="-0.17787 0.025 -0.025"/>
      <geometry>
        <mesh filename="package://mistletoe_description/meshes/ACTUATOR_V2.1__KNEE__v10_1.stl" scale="0.001 0.001 0.001"/>
      </geometry>
    </collision>
  </link>
  <link name="Hip_1">
    <inertial>
      <origin rpy="0 0 0" xyz="-0.1675167715088863 0.008238257074782459 -5.174132261531739e-09"/>
      <mass value="0.5600707780907046"/>
      <inertia ixx="0.000428" ixy="0.000319" ixz="-0.0" iyy="0.004847" iyz="-0.0" izz="0.004917"/>
    </inertial>
    <visual>
      <origin rpy="0 0 0" xyz="-0.255776 -0.0 -0.025"/>
      <geometry>
        <mesh filename="package://mistletoe_description/meshes/Hip_1.stl" scale="0.001 0.001 0.001"/>
      </geometry>
      <material name="plastic_glossy_black"/>
    </visual>
    <collision>
      <origin rpy="0 0 0" xyz="-0.255776 -0.0 -0.025"/>
      <geometry>
        <mesh filename="package://mistletoe_description/meshes/Hip_1.stl" scale="0.001 0.001 0.001"/>
      </geometry>
    </collision>
  </link>
  <link name="Hip_2">
    <inertial>
      <origin rpy="0 0 0" xyz="-0.1675167715088863 -0.008238257074782096 5.174132615415328e-09"/>
      <mass value="0.5600707780907046"/>
      <inertia ixx="0.000428" ixy="-0.000319" ixz="0.0" iyy="0.004847" iyz="-0.0" izz="0.004917"/>
    </inertial>
    <visual>
      <origin rpy="0 0 0" xyz="-0.255776 -0.243608 -0.025"/>
      <geometry>
        <mesh filename="package://mistletoe_description/meshes/Hip_2.stl" scale="0.001 0.001 0.001"/>
      </geometry>
      <material name="plastic_glossy_black"/>
    </visual>
    <collision>
      <origin rpy="0 0 0" xyz="-0.255776 -0.243608 -0.025"/>
      <geometry>
        <mesh filename="package://mistletoe_description/meshes/Hip_2.stl" scale="0.001 0.001 0.001"/>
      </geometry>
    </collision>
  </link>
  <link name="LEG_2_THIGH">
    <inertial>
      <origin rpy="0 0 0" xyz="-0.05309590553246825 0.0602565020545649 6.906335525407037e-06"/>
      <mass value="0.6687419456686833"/>
      <inertia ixx="0.000581" ixy="0.000492" ixz="-0.0" iyy="0.003897" iyz="0.0" izz="0.004059"/>
    </inertial>
    <visual>
      <origin rpy="0 0 0" xyz="-0.17787 -0.268608 -0.025"/>
      <geometry>
        <mesh filename="package://mistletoe_description/meshes/ACTUATOR_V2.1__KNEE__v10_2.stl" scale="0.001 0.001 0.001"/>
      </geometry>
      <material name="plastic_glossy_black"/>
    </visual>
    <collision>
      <origin rpy="0 0 0" xyz="-0.17787 -0.268608 -0.025"/>
      <geometry>
        <mesh filename="package://mistletoe_description/meshes/ACTUATOR_V2.1__KNEE__v10_2.stl" scale="0.001 0.001 0.001"/>
      </geometry>
    </collision>
  </link>
  <link name="LEG_2_FOOT">
    <inertial>
      <origin rpy="0 0 0" xyz="0.059695509319545356 -0.021647688090992268 -0.034465225223213346"/>
      <mass value="0.0707595437253254"/>
      <inertia ixx="5.5e-05" ixy="4e-06" ixz="8e-05" iyy="0.000193" iyz="-3e-06" izz="0.000147"/>
    </inertial>
    <visual>
      <origin rpy="0 0 0" xyz="-0.002 -0.313108 -0.025"/>
      <geometry>
        <mesh filename="package://mistletoe_description/meshes/ANKLE_v4_2.stl" scale="0.001 0.001 0.001"/>
      </geometry>
      <material name="plastic_glossy_black"/>
    </visual>
    <collision>
      <origin rpy="0 0 0" xyz="-0.002 -0.313108 -0.025"/>
      <geometry>
        <mesh filename="package://mistletoe_description/meshes/ANKLE_v4_2.stl" scale="0.001 0.001 0.001"/>
      </geometry>
    </collision>
  </link>
  <link name="Hip_3">
    <inertial>
      <origin rpy="0 0 0" xyz="0.16751677150888733 0.008238257074779359 5.174144071529163e-09"/>
      <mass value="0.5600707780907046"/>
      <inertia ixx="0.000428" ixy="-0.000319" ixz="-0.0" iyy="0.004847" iyz="0.0" izz="0.004917"/>
    </inertial>
    <visual>
      <origin rpy="0 0 0" xyz="0.389589 0.0 -0.025"/>
      <geometry>
        <mesh filename="package://mistletoe_description/meshes/Hip_3.stl" scale="0.001 0.001 0.001"/>
      </geometry>
      <material name="plastic_glossy_black"/>
    </visual>
    <collision>
      <origin rpy="0 0 0" xyz="0.389589 0.0 -0.025"/>
      <geometry>
        <mesh filename="package://mistletoe_description/meshes/Hip_3.stl" scale="0.001 0.001 0.001"/>
      </geometry>
    </collision>
  </link>
  <link name="Hip_4">
    <inertial>
      <origin rpy="0 0 0" xyz="0.16751677150888733 -0.008238257074783317 -5.174120409900951e-09"/>
      <mass value="0.5600707780907046"/>
      <inertia ixx="0.000428" ixy="0.000319" ixz="0.0" iyy="0.004847" iyz="0.0" izz="0.004917"/>
    </inertial>
    <visual>
      <origin rpy="0 0 0" xyz="0.389589 -0.243608 -0.025"/>
      <geometry>
        <mesh filename="package://mistletoe_description/meshes/Hip_4.stl" scale="0.001 0.001 0.001"/>
      </geometry>
      <material name="plastic_glossy_black"/>
    </visual>
    <collision>
      <origin rpy="0 0 0" xyz="0.389589 -0.243608 -0.025"/>
      <geometry>
        <mesh filename="package://mistletoe_description/meshes/Hip_4.stl" scale="0.001 0.001 0.001"/>
      </geometry>
    </collision>
  </link>
  <link name="LEG_3_THIGH">
    <inertial>
      <origin rpy="0 0 0" xyz="0.05309590553246918 -0.06025650205456722 6.906335536540492e-06"/>
      <mass value="0.6687419456686833"/>
      <inertia ixx="0.000581" ixy="0.000492" ixz="0.0" iyy="0.003897" iyz="-0.0" izz="0.004059"/>
    </inertial>
    <visual>
      <origin rpy="0 0 0" xyz="0.311683 0.025 -0.025"/>
      <geometry>
        <mesh filename="package://mistletoe_description/meshes/ACTUATOR_V2.1__KNEE__v10_3.stl" scale="0.001 0.001 0.001"/>
      </geometry>
      <material name="plastic_glossy_black"/>
    </visual>
    <collision>
      <origin rpy="0 0 0" xyz="0.311683 0.025 -0.025"/>
      <geometry>
        <mesh filename="package://mistletoe_description/meshes/ACTUATOR_V2.1__KNEE__v10_3.stl" scale="0.001 0.001 0.001"/>
      </geometry>
    </collision>
  </link>
  <link name="LEG_4_THIGH">
    <inertial>
      <origin rpy="0 0 0" xyz="0.05309590553246907 0.06025650205456318 -6.906335511872724e-06"/>
      <mass value="0.6687419456686833"/>
      <inertia ixx="0.000581" ixy="-0.000492" ixz="-0.0" iyy="0.003897" iyz="-0.0" izz="0.004059"/>
    </inertial>
    <visual>
      <origin rpy="0 0 0" xyz="0.311683 -0.268608 -0.025"/>
      <geometry>
        <mesh filename="package://mistletoe_description/meshes/ACTUATOR_V2.1__KNEE__v10_4.stl" scale="0.001 0.001 0.001"/>
      </geometry>
      <material name="plastic_glossy_black"/>
    </visual>
    <collision>
      <origin rpy="0 0 0" xyz="0.311683 -0.268608 -0.025"/>
      <geometry>
        <mesh filename="package://mistletoe_description/meshes/ACTUATOR_V2.1__KNEE__v10_4.stl" scale="0.001 0.001 0.001"/>
      </geometry>
    </collision>
  </link>
  <link name="LEG_3_FOOT">
    <inertial>
      <origin rpy="0 0 0" xyz="-0.059695515250226594 -0.021647688090993877 -0.034465214950958015"/>
      <mass value="0.0707595437253254"/>
      <inertia ixx="5.5e-05" ixy="-4e-06" ixz="-8e-05" iyy="0.000193" iyz="-3e-06" izz="0.000147"/>
    </inertial>
    <visual>
      <origin rpy="0 0 0" xyz="0.135813 -0.313108 -0.025"/>
      <geometry>
        <mesh filename="package://mistletoe_description/meshes/ANKLE_v4_3.stl" scale="0.001 0.001 0.001"/>
      </geometry>
      <material name="plastic_glossy_black"/>
    </visual>
    <collision>
      <origin rpy="0 0 0" xyz="0.135813 -0.313108 -0.025"/>
      <geometry>
        <mesh filename="package://mistletoe_description/meshes/ANKLE_v4_3.stl" scale="0.001 0.001 0.001"/>
      </geometry>
    </collision>
  </link>
  <link name="LEG_4_FOOT">
    <inertial>
      <origin rpy="0 0 0" xyz="-0.05969550931954576 0.02164768809099009 -0.03446522522320032"/>
      <mass value="0.0707595437253254"/>
      <inertia ixx="5.5e-05" ixy="4e-06" ixz="-8e-05" iyy="0.000193" iyz="3e-06" izz="0.000147"/>
    </inertial>
    <visual>
      <origin rpy="0 0 0" xyz="0.135813 0.0695 -0.025"/>
      <geometry>
        <mesh filename="package://mistletoe_description/meshes/ANKLE_v4_4.stl" scale="0.001 0.001 0.001"/>
      </geometry>
      <material name="plastic_glossy_black"/>
    </visual>
    <collision>
      <origin rpy="0 0 0" xyz="0.135813 0.0695 -0.025"/>
      <geometry>
        <mesh filename="package://mistletoe_description/meshes/ANKLE_v4_4.stl" scale="0.001 0.001 0.001"/>
      </geometry>
    </collision>
  </link>
  <joint name="LEG_3_KFE" type="continuous">
    <origin rpy="0 0 0" xyz="-0.17587 -0.0445 0.0"/>
    <parent link="LEG_1_THIGH"/>
    <child link="LEG_1_FOOT"/>
    <axis xyz="0.0 -1.0 0.0"/>
  </joint>
  <joint name="LEG_3_HFE" type="continuous">
    <origin rpy="0 0 0" xyz="-0.077906 -0.025 0.0"/>
    <parent link="Hip_1"/>
    <child link="LEG_1_THIGH"/>
    <axis xyz="0.0 1.0 -0.0"/>
  </joint>
  <joint name="LEG_3_HAA" type="continuous">
    <origin rpy="0 0 0" xyz="0.255776 0.0 0.025"/>
    <parent link="base"/>
    <child link="Hip_1"/>
    <axis xyz="-1.0 0.0 0.0"/>
  </joint>
  <joint name="LEG_4_HAA" type="continuous">
    <origin rpy="0 0 0" xyz="0.255776 0.243608 0.025"/>
    <parent link="base"/>
    <child link="Hip_2"/>
    <axis xyz="1.0 0.0 -0.0"/>
  </joint>
  <joint name="LEG_4_HFE" type="continuous">
    <origin rpy="0 0 0" xyz="-0.077906 0.025 0.0"/>
    <parent link="Hip_2"/>
    <child link="LEG_2_THIGH"/>
    <axis xyz="0.0 -1.0 0.0"/>
  </joint>
  <joint name="LEG_4_KFE" type="continuous">
    <origin rpy="0 0 0" xyz="-0.17587 0.0445 0.0"/>
    <parent link="LEG_2_THIGH"/>
    <child link="LEG_2_FOOT"/>
    <axis xyz="0.0 1.0 -0.0"/>
  </joint>
  <joint name="LEG_1_HAA" type="continuous">
    <origin rpy="0 0 0" xyz="-0.389589 0.0 0.025"/>
    <parent link="base"/>
    <child link="Hip_3"/>
    <axis xyz="1.0 0.0 -0.0"/>
  </joint>
  <joint name="LEG_2_HAA" type="continuous">
    <origin rpy="0 0 0" xyz="-0.389589 0.243608 0.025"/>
    <parent link="base"/>
    <child link="Hip_4"/>
    <axis xyz="1.0 0.0 -0.0"/>
  </joint>
  <joint name="LEG_1_HFE" type="continuous">
    <origin rpy="0 0 0" xyz="0.077906 -0.025 0.0"/>
    <parent link="Hip_3"/>
    <child link="LEG_3_THIGH"/>
    <axis xyz="-0.0 1.0 -0.0"/>
  </joint>
  <joint name="LEG_2_HFE" type="continuous">
    <origin rpy="0 0 0" xyz="0.077906 0.025 0.0"/>
    <parent link="Hip_4"/>
    <child link="LEG_4_THIGH"/>
    <axis xyz="-0.0 -1.0 -0.0"/>
  </joint>
  <joint name="LEG_2_KFE" type="continuous">
    <origin rpy="0 0 0" xyz="0.17587 0.0445 0.0"/>
    <parent link="LEG_4_THIGH"/>
    <child link="LEG_3_FOOT"/>
    <axis xyz="-0.0 1.0 0.0"/>
  </joint>
  <joint name="LEG_1_KFE" type="continuous">
    <origin rpy="0 0 0" xyz="0.17587 -0.0445 0.0"/>
    <parent link="LEG_3_THIGH"/>
    <child link="LEG_4_FOOT"/>
    <axis xyz="-0.0 -1.0 0.0"/>
  </joint>
</robot>
