<?xml version="1.0" ?>
<!-- =================================================================================== -->
<!-- |    This document was autogenerated by xacro from mistletoe.xacro                | -->
<!-- |    EDITING THIS FILE BY HAND IS NOT RECOMMENDED                                 | -->
<!-- =================================================================================== -->
<robot name="mistletoe">
  <material name="silver_default">
    <color rgba="0.700 0.700 0.700 1.000"/>
  </material>
  <material name="plastic_glossy_black">
    <color rgba="0.09803921568627451 0.09803921568627451 0.09803921568627451 1.0"/>
  </material>
  <transmission name="KFE3_tran">
    <type>transmission_interface/SimpleTransmission</type>
    <joint name="KFE3">
      <hardwareInterface>hardware_interface/EffortJointInterface</hardwareInterface>
    </joint>
    <actuator name="KFE3_actr">
      <hardwareInterface>hardware_interface/EffortJointInterface</hardwareInterface>
      <mechanicalReduction>1</mechanicalReduction>
    </actuator>
  </transmission>
  <transmission name="HFE3_tran">
    <type>transmission_interface/SimpleTransmission</type>
    <joint name="HFE3">
      <hardwareInterface>hardware_interface/EffortJointInterface</hardwareInterface>
    </joint>
    <actuator name="HFE3_actr">
      <hardwareInterface>hardware_interface/EffortJointInterface</hardwareInterface>
      <mechanicalReduction>1</mechanicalReduction>
    </actuator>
  </transmission>
  <transmission name="HAA3_tran">
    <type>transmission_interface/SimpleTransmission</type>
    <joint name="HAA3">
      <hardwareInterface>hardware_interface/EffortJointInterface</hardwareInterface>
    </joint>
    <actuator name="HAA3_actr">
      <hardwareInterface>hardware_interface/EffortJointInterface</hardwareInterface>
      <mechanicalReduction>1</mechanicalReduction>
    </actuator>
  </transmission>
  <transmission name="HAA4_tran">
    <type>transmission_interface/SimpleTransmission</type>
    <joint name="HAA4">
      <hardwareInterface>hardware_interface/EffortJointInterface</hardwareInterface>
    </joint>
    <actuator name="HAA4_actr">
      <hardwareInterface>hardware_interface/EffortJointInterface</hardwareInterface>
      <mechanicalReduction>1</mechanicalReduction>
    </actuator>
  </transmission>
  <transmission name="HFE4_tran">
    <type>transmission_interface/SimpleTransmission</type>
    <joint name="HFE4">
      <hardwareInterface>hardware_interface/EffortJointInterface</hardwareInterface>
    </joint>
    <actuator name="HFE4_actr">
      <hardwareInterface>hardware_interface/EffortJointInterface</hardwareInterface>
      <mechanicalReduction>1</mechanicalReduction>
    </actuator>
  </transmission>
  <transmission name="KFE4_tran">
    <type>transmission_interface/SimpleTransmission</type>
    <joint name="KFE4">
      <hardwareInterface>hardware_interface/EffortJointInterface</hardwareInterface>
    </joint>
    <actuator name="KFE4_actr">
      <hardwareInterface>hardware_interface/EffortJointInterface</hardwareInterface>
      <mechanicalReduction>1</mechanicalReduction>
    </actuator>
  </transmission>
  <transmission name="HAA1_tran">
    <type>transmission_interface/SimpleTransmission</type>
    <joint name="HAA1">
      <hardwareInterface>hardware_interface/EffortJointInterface</hardwareInterface>
    </joint>
    <actuator name="HAA1_actr">
      <hardwareInterface>hardware_interface/EffortJointInterface</hardwareInterface>
      <mechanicalReduction>1</mechanicalReduction>
    </actuator>
  </transmission>
  <transmission name="HAA2_tran">
    <type>transmission_interface/SimpleTransmission</type>
    <joint name="HAA2">
      <hardwareInterface>hardware_interface/EffortJointInterface</hardwareInterface>
    </joint>
    <actuator name="HAA2_actr">
      <hardwareInterface>hardware_interface/EffortJointInterface</hardwareInterface>
      <mechanicalReduction>1</mechanicalReduction>
    </actuator>
  </transmission>
  <transmission name="HFE1_tran">
    <type>transmission_interface/SimpleTransmission</type>
    <joint name="HFE1">
      <hardwareInterface>hardware_interface/EffortJointInterface</hardwareInterface>
    </joint>
    <actuator name="HFE1_actr">
      <hardwareInterface>hardware_interface/EffortJointInterface</hardwareInterface>
      <mechanicalReduction>1</mechanicalReduction>
    </actuator>
  </transmission>
  <transmission name="HFE2_tran">
    <type>transmission_interface/SimpleTransmission</type>
    <joint name="HFE2">
      <hardwareInterface>hardware_interface/EffortJointInterface</hardwareInterface>
    </joint>
    <actuator name="HFE2_actr">
      <hardwareInterface>hardware_interface/EffortJointInterface</hardwareInterface>
      <mechanicalReduction>1</mechanicalReduction>
    </actuator>
  </transmission>
  <transmission name="Revolute 27_tran">
    <type>transmission_interface/SimpleTransmission</type>
    <joint name="Revolute 27">
      <hardwareInterface>hardware_interface/EffortJointInterface</hardwareInterface>
    </joint>
    <actuator name="Revolute 27_actr">
      <hardwareInterface>hardware_interface/EffortJointInterface</hardwareInterface>
      <mechanicalReduction>1</mechanicalReduction>
    </actuator>
  </transmission>
  <transmission name="Revolute 28_tran">
    <type>transmission_interface/SimpleTransmission</type>
    <joint name="Revolute 28">
      <hardwareInterface>hardware_interface/EffortJointInterface</hardwareInterface>
    </joint>
    <actuator name="Revolute 28_actr">
      <hardwareInterface>hardware_interface/EffortJointInterface</hardwareInterface>
      <mechanicalReduction>1</mechanicalReduction>
    </actuator>
  </transmission>
  <link name="base_link">
    <inertial>
      <origin rpy="0 0 0" xyz="-0.06657859086794649 0.1208022759873019 0.027661254547308046"/>
      <mass value="2.781822888066483"/>
      <inertia ixx="0.012347" ixy="-3e-06" ixz="-4.1e-05" iyy="0.169247" iyz="0.0" izz="0.177361"/>
    </inertial>
    <visual>
      <origin rpy="0 0 0" xyz="0 0 0"/>
      <geometry>
        <mesh filename="package://mistletoe_description/meshes/base_link.stl" scale="0.001 0.001 0.001"/>
      </geometry>
      <material name="plastic_glossy_black"/>
    </visual>
    <collision>
      <origin rpy="0 0 0" xyz="0 0 0"/>
      <geometry>
        <mesh filename="package://mistletoe_description/meshes/base_link.stl" scale="0.001 0.001 0.001"/>
      </geometry>
    </collision>
  </link>
  <link name="ANKLE_v4_1">
    <inertial>
      <origin rpy="0 0 0" xyz="-3.940693174275811e-07 0.02214768809098814 -0.06893004017418905"/>
      <mass value="0.0707595437253254"/>
      <inertia ixx="0.000194" ixy="0.0" ixz="-0.0" iyy="0.000193" iyz="5e-06" izz="8e-06"/>
    </inertial>
    <visual>
      <origin rpy="0 0 0" xyz="-0.17787 0.071 0.15087"/>
      <geometry>
        <mesh filename="package://mistletoe_description/meshes/ANKLE_v4_1.stl" scale="0.001 0.001 0.001"/>
      </geometry>
      <material name="plastic_glossy_black"/>
    </visual>
    <collision>
      <origin rpy="0 0 0" xyz="-0.17787 0.071 0.15087"/>
      <geometry>
        <mesh filename="package://mistletoe_description/meshes/ANKLE_v4_1.stl" scale="0.001 0.001 0.001"/>
      </geometry>
    </collision>
  </link>
  <link name="ACTUATOR_V2.1__KNEE__v10_1">
    <inertial>
      <origin rpy="0 0 0" xyz="6.506335524347762e-06 -0.06075650205456666 -0.05309550553247122"/>
      <mass value="0.6687419456686833"/>
      <inertia ixx="0.004059" ixy="-0.0" ixz="-0.0" iyy="0.003897" iyz="-0.000492" izz="0.000581"/>
    </inertial>
    <visual>
      <origin rpy="0 0 0" xyz="-0.17787 0.026 -0.025"/>
      <geometry>
        <mesh filename="package://mistletoe_description/meshes/ACTUATOR_V2.1__KNEE__v10_1.stl" scale="0.001 0.001 0.001"/>
      </geometry>
      <material name="plastic_glossy_black"/>
    </visual>
    <collision>
      <origin rpy="0 0 0" xyz="-0.17787 0.026 -0.025"/>
      <geometry>
        <mesh filename="package://mistletoe_description/meshes/ACTUATOR_V2.1__KNEE__v10_1.stl" scale="0.001 0.001 0.001"/>
      </geometry>
    </collision>
  </link>
  <link name="Hip_1">
    <inertial>
      <origin rpy="0 0 0" xyz="-0.1675167715088861 0.008238257074781406 -5.1741353111756094e-09"/>
      <mass value="0.5600707780907046"/>
      <inertia ixx="0.000428" ixy="0.000319" ixz="-0.0" iyy="0.004847" iyz="-0.0" izz="0.004917"/>
    </inertial>
    <visual>
      <origin rpy="0 0 0" xyz="-0.255776 0.001 -0.025"/>
      <geometry>
        <mesh filename="package://mistletoe_description/meshes/Hip_1.stl" scale="0.001 0.001 0.001"/>
      </geometry>
      <material name="plastic_glossy_black"/>
    </visual>
    <collision>
      <origin rpy="0 0 0" xyz="-0.255776 0.001 -0.025"/>
      <geometry>
        <mesh filename="package://mistletoe_description/meshes/Hip_1.stl" scale="0.001 0.001 0.001"/>
      </geometry>
    </collision>
  </link>
  <link name="Hip_2">
    <inertial>
      <origin rpy="0 0 0" xyz="-0.1675167715088861 -0.00823825707478365 5.174126540413715e-09"/>
      <mass value="0.5600707780907046"/>
      <inertia ixx="0.000428" ixy="-0.000319" ixz="0.0" iyy="0.004847" iyz="-0.0" izz="0.004917"/>
    </inertial>
    <visual>
      <origin rpy="0 0 0" xyz="-0.255776 -0.242608 -0.025"/>
      <geometry>
        <mesh filename="package://mistletoe_description/meshes/Hip_2.stl" scale="0.001 0.001 0.001"/>
      </geometry>
      <material name="plastic_glossy_black"/>
    </visual>
    <collision>
      <origin rpy="0 0 0" xyz="-0.255776 -0.242608 -0.025"/>
      <geometry>
        <mesh filename="package://mistletoe_description/meshes/Hip_2.stl" scale="0.001 0.001 0.001"/>
      </geometry>
    </collision>
  </link>
  <link name="ACTUATOR_V2.1__KNEE__v10_2">
    <inertial>
      <origin rpy="0 0 0" xyz="-7.306335524759344e-06 0.06075650205456229 -0.05309550553247524"/>
      <mass value="0.6687419456686833"/>
      <inertia ixx="0.004059" ixy="-0.0" ixz="0.0" iyy="0.003897" iyz="0.000492" izz="0.000581"/>
    </inertial>
    <visual>
      <origin rpy="0 0 0" xyz="-0.17787 -0.267608 -0.025"/>
      <geometry>
        <mesh filename="package://mistletoe_description/meshes/ACTUATOR_V2.1__KNEE__v10_2.stl" scale="0.001 0.001 0.001"/>
      </geometry>
      <material name="plastic_glossy_black"/>
    </visual>
    <collision>
      <origin rpy="0 0 0" xyz="-0.17787 -0.267608 -0.025"/>
      <geometry>
        <mesh filename="package://mistletoe_description/meshes/ACTUATOR_V2.1__KNEE__v10_2.stl" scale="0.001 0.001 0.001"/>
      </geometry>
    </collision>
  </link>
  <link name="ANKLE_v4_2">
    <inertial>
      <origin rpy="0 0 0" xyz="-4.0593068142968924e-07 -0.02214768809099732 -0.06893004017419127"/>
      <mass value="0.0707595437253254"/>
      <inertia ixx="0.000194" ixy="0.0" ixz="0.0" iyy="0.000193" iyz="-5e-06" izz="8e-06"/>
    </inertial>
    <visual>
      <origin rpy="0 0 0" xyz="-0.17787 -0.312608 0.15087"/>
      <geometry>
        <mesh filename="package://mistletoe_description/meshes/ANKLE_v4_2.stl" scale="0.001 0.001 0.001"/>
      </geometry>
      <material name="plastic_glossy_black"/>
    </visual>
    <collision>
      <origin rpy="0 0 0" xyz="-0.17787 -0.312608 0.15087"/>
      <geometry>
        <mesh filename="package://mistletoe_description/meshes/ANKLE_v4_2.stl" scale="0.001 0.001 0.001"/>
      </geometry>
    </collision>
  </link>
  <link name="Hip_3">
    <inertial>
      <origin rpy="0 0 0" xyz="0.16751677150888714 0.008238257074780413 5.174135425667359e-09"/>
      <mass value="0.5600707780907046"/>
      <inertia ixx="0.000428" ixy="-0.000319" ixz="-0.0" iyy="0.004847" iyz="0.0" izz="0.004917"/>
    </inertial>
    <visual>
      <origin rpy="0 0 0" xyz="0.389589 0.001 -0.025"/>
      <geometry>
        <mesh filename="package://mistletoe_description/meshes/Hip_3.stl" scale="0.001 0.001 0.001"/>
      </geometry>
      <material name="plastic_glossy_black"/>
    </visual>
    <collision>
      <origin rpy="0 0 0" xyz="0.389589 0.001 -0.025"/>
      <geometry>
        <mesh filename="package://mistletoe_description/meshes/Hip_3.stl" scale="0.001 0.001 0.001"/>
      </geometry>
    </collision>
  </link>
  <link name="Hip_4">
    <inertial>
      <origin rpy="0 0 0" xyz="0.16751677150888733 -0.008238257074784622 -5.174131970098195e-09"/>
      <mass value="0.5600707780907046"/>
      <inertia ixx="0.000428" ixy="0.000319" ixz="0.0" iyy="0.004847" iyz="0.0" izz="0.004917"/>
    </inertial>
    <visual>
      <origin rpy="0 0 0" xyz="0.389589 -0.242608 -0.025"/>
      <geometry>
        <mesh filename="package://mistletoe_description/meshes/Hip_4.stl" scale="0.001 0.001 0.001"/>
      </geometry>
      <material name="plastic_glossy_black"/>
    </visual>
    <collision>
      <origin rpy="0 0 0" xyz="0.389589 -0.242608 -0.025"/>
      <geometry>
        <mesh filename="package://mistletoe_description/meshes/Hip_4.stl" scale="0.001 0.001 0.001"/>
      </geometry>
    </collision>
  </link>
  <link name="ACTUATOR_V2.1__KNEE__v10_3">
    <inertial>
      <origin rpy="0 0 0" xyz="7.306335524315255e-06 -0.060756502054566924 -0.053095505532472546"/>
      <mass value="0.6687419456686833"/>
      <inertia ixx="0.004059" ixy="-0.0" ixz="-0.0" iyy="0.003897" iyz="-0.000492" izz="0.000581"/>
    </inertial>
    <visual>
      <origin rpy="0 0 0" xyz="0.311683 0.026 -0.025"/>
      <geometry>
        <mesh filename="package://mistletoe_description/meshes/ACTUATOR_V2.1__KNEE__v10_3.stl" scale="0.001 0.001 0.001"/>
      </geometry>
      <material name="plastic_glossy_black"/>
    </visual>
    <collision>
      <origin rpy="0 0 0" xyz="0.311683 0.026 -0.025"/>
      <geometry>
        <mesh filename="package://mistletoe_description/meshes/ACTUATOR_V2.1__KNEE__v10_3.stl" scale="0.001 0.001 0.001"/>
      </geometry>
    </collision>
  </link>
  <link name="ACTUATOR_V2.1__KNEE__v10_4">
    <inertial>
      <origin rpy="0 0 0" xyz="-6.506335524625317e-06 0.06075650205456207 -0.05309550553247644"/>
      <mass value="0.6687419456686833"/>
      <inertia ixx="0.004059" ixy="-0.0" ixz="0.0" iyy="0.003897" iyz="0.000492" izz="0.000581"/>
    </inertial>
    <visual>
      <origin rpy="0 0 0" xyz="0.311683 -0.267608 -0.025"/>
      <geometry>
        <mesh filename="package://mistletoe_description/meshes/ACTUATOR_V2.1__KNEE__v10_4.stl" scale="0.001 0.001 0.001"/>
      </geometry>
      <material name="plastic_glossy_black"/>
    </visual>
    <collision>
      <origin rpy="0 0 0" xyz="0.311683 -0.267608 -0.025"/>
      <geometry>
        <mesh filename="package://mistletoe_description/meshes/ACTUATOR_V2.1__KNEE__v10_4.stl" scale="0.001 0.001 0.001"/>
      </geometry>
    </collision>
  </link>
  <link name="ANKLE_v4_3">
    <inertial>
      <origin rpy="0 0 0" xyz="4.0593068234562324e-07 0.022147688090987667 -0.06893004017418988"/>
      <mass value="0.0707595437253254"/>
      <inertia ixx="0.000194" ixy="0.0" ixz="-0.0" iyy="0.000193" iyz="5e-06" izz="8e-06"/>
    </inertial>
    <visual>
      <origin rpy="0 0 0" xyz="0.311683 0.071 0.15087"/>
      <geometry>
        <mesh filename="package://mistletoe_description/meshes/ANKLE_v4_3.stl" scale="0.001 0.001 0.001"/>
      </geometry>
      <material name="plastic_glossy_black"/>
    </visual>
    <collision>
      <origin rpy="0 0 0" xyz="0.311683 0.071 0.15087"/>
      <geometry>
        <mesh filename="package://mistletoe_description/meshes/ANKLE_v4_3.stl" scale="0.001 0.001 0.001"/>
      </geometry>
    </collision>
  </link>
  <link name="ANKLE_v4_4">
    <inertial>
      <origin rpy="0 0 0" xyz="3.9406931612306906e-07 -0.022147688090997875 -0.0689300401741931"/>
      <mass value="0.0707595437253254"/>
      <inertia ixx="0.000194" ixy="0.0" ixz="0.0" iyy="0.000193" iyz="-5e-06" izz="8e-06"/>
    </inertial>
    <visual>
      <origin rpy="0 0 0" xyz="0.311683 -0.312608 0.15087"/>
      <geometry>
        <mesh filename="package://mistletoe_description/meshes/ANKLE_v4_4.stl" scale="0.001 0.001 0.001"/>
      </geometry>
      <material name="plastic_glossy_black"/>
    </visual>
    <collision>
      <origin rpy="0 0 0" xyz="0.311683 -0.312608 0.15087"/>
      <geometry>
        <mesh filename="package://mistletoe_description/meshes/ANKLE_v4_4.stl" scale="0.001 0.001 0.001"/>
      </geometry>
    </collision>
  </link>
  <joint name="KFE3" type="continuous">
    <origin rpy="0 0 0" xyz="0.0 -0.045 -0.17587"/>
    <parent link="ACTUATOR_V2.1__KNEE__v10_1"/>
    <child link="ANKLE_v4_1"/>
    <axis xyz="-0.0 -1.0 0.0"/>
  </joint>
  <joint name="HFE3" type="continuous">
    <origin rpy="0 0 0" xyz="-0.077906 -0.025 0.0"/>
    <parent link="Hip_1"/>
    <child link="ACTUATOR_V2.1__KNEE__v10_1"/>
    <axis xyz="0.0 1.0 -0.0"/>
  </joint>
  <joint name="HAA3" type="continuous">
    <origin rpy="0 0 0" xyz="0.255776 -0.001 0.025"/>
    <parent link="base_link"/>
    <child link="Hip_1"/>
    <axis xyz="-1.0 0.0 0.0"/>
  </joint>
  <joint name="HAA4" type="continuous">
    <origin rpy="0 0 0" xyz="0.255776 0.242608 0.025"/>
    <parent link="base_link"/>
    <child link="Hip_2"/>
    <axis xyz="1.0 0.0 -0.0"/>
  </joint>
  <joint name="HFE4" type="continuous">
    <origin rpy="0 0 0" xyz="-0.077906 0.025 0.0"/>
    <parent link="Hip_2"/>
    <child link="ACTUATOR_V2.1__KNEE__v10_2"/>
    <axis xyz="0.0 -1.0 0.0"/>
  </joint>
  <joint name="KFE4" type="continuous">
    <origin rpy="0 0 0" xyz="0.0 0.045 -0.17587"/>
    <parent link="ACTUATOR_V2.1__KNEE__v10_2"/>
    <child link="ANKLE_v4_2"/>
    <axis xyz="-0.0 1.0 -0.0"/>
  </joint>
  <joint name="HAA1" type="continuous">
    <origin rpy="0 0 0" xyz="-0.389589 -0.001 0.025"/>
    <parent link="base_link"/>
    <child link="Hip_3"/>
    <axis xyz="1.0 0.0 -0.0"/>
  </joint>
  <joint name="HAA2" type="continuous">
    <origin rpy="0 0 0" xyz="-0.389589 0.242608 0.025"/>
    <parent link="base_link"/>
    <child link="Hip_4"/>
    <axis xyz="1.0 0.0 -0.0"/>
  </joint>
  <joint name="HFE1" type="continuous">
    <origin rpy="0 0 0" xyz="0.077906 -0.025 0.0"/>
    <parent link="Hip_3"/>
    <child link="ACTUATOR_V2.1__KNEE__v10_3"/>
    <axis xyz="-0.0 1.0 -0.0"/>
  </joint>
  <joint name="HFE2" type="continuous">
    <origin rpy="0 0 0" xyz="0.077906 0.025 0.0"/>
    <parent link="Hip_4"/>
    <child link="ACTUATOR_V2.1__KNEE__v10_4"/>
    <axis xyz="-0.0 -1.0 0.0"/>
  </joint>
  <joint name="Revolute 27" type="continuous">
    <origin rpy="0 0 0" xyz="0.0 -0.045 -0.17587"/>
    <parent link="ACTUATOR_V2.1__KNEE__v10_3"/>
    <child link="ANKLE_v4_3"/>
    <axis xyz="0.0 -1.0 0.0"/>
  </joint>
  <joint name="Revolute 28" type="continuous">
    <origin rpy="0 0 0" xyz="0.0 0.045 -0.17587"/>
    <parent link="ACTUATOR_V2.1__KNEE__v10_4"/>
    <child link="ANKLE_v4_4"/>
    <axis xyz="0.0 1.0 -0.0"/>
  </joint>
</robot>
